Workbook

Sheet Boss Calculator v1
C5: T4 | E5: T5 | H5: T6 | J5: T7 | N5: T8 | P5: T9
A7: TOTAL | B7: Compos | C7: Abyssal | D7: Celestial | E7: Nidhogg | F7: Chaos (rouge) | G7: Order (blue) | H7: Normal | I7: Giga | J7: Dodo Bleu | K7: Dodo Rouge | L7: W. Reaper | M7: W. Giga | N7: Ascension | O7: Descension | P7: 1 Seal | Q7: 2 Seal | R7: 3 Seal | S7: 4 Seal | T7: Cube
A8: =SUM(C8:T8) -> 20 | B8: Artefact | C8: {=Feuille1!C8:C48*$C$50} -> 20 | D8: {=Feuille1!D8:D48*$D$50} -> 0 | E8: {=Feuille1!E8:E48*$E$50} -> 0 | F8: {=Feuille1!F8:F48*$F$50} -> 0 | G8: {=Feuille1!G8:G48*$G$50} -> 0 | H8: {=Feuille1!H8:H48*$H$50} -> 0 | I8: {=Feuille1!I8:I48*$I$50} -> 0 | J8: {=Feuille1!J8:J48*$J$50} -> 0 | K8: {=Feuille1!K8:K48*$K$50} -> 0 | L8: {=Feuille1!L8:L48*$L$50} -> 0 | M8: {=Feuille1!M8:M48*$M$50} -> 0 | N8: {=Feuille1!N8:N48*$N$50} -> 0 | O8: {=Feuille1!O8:O48*$O$50} -> 0 | P8: {=Feuille1!P8:P48*$P$50} -> 0 | Q8: {=Feuille1!Q8:Q48*$Q$50} -> 0 | R8: {=Feuille1!R8:R48*$R$50} -> 0 | S8: {=Feuille1!S8:S48*$S$50} -> 0 | T8: {=Feuille1!T8:T48*$T$50} -> 0
A9: =SUM(C9:T9) -> 0 | B9: Abyssal Warfare Key | C9: 0 | D9: 0 | E9: 0 | F9: 0 | G9: 0 | H9: 0 | I9: 0 | J9: 0 | K9: 0 | L9: 0 | M9: 0 | N9: 0 | O9: 0 | P9: 0 | Q9: 0 | R9: 0 | S9: 0 | T9: 0
A10: =SUM(C10:T10) -> 0 | B10: Celestial Warfare key | C10: 0 | D10: 0 | E10: 0 | F10: 0 | G10: 0 | H10: 0 | I10: 0 | J10: 0 | K10: 0 | L10: 0 | M10: 0 | N10: 0 | O10: 0 | P10: 0 | Q10: 0 | R10: 0 | S10: 0 | T10: 0
A11: =SUM(C11:T11) -> 10 | B11: Ancient token Cluster | C11: 10 | D11: 0 | E11: 0 | F11: 0 | G11: 0 | H11: 0 | I11: 0 | J11: 0 | K11: 0 | L11: 0 | M11: 0 | N11: 0 | O11: 0 | P11: 0 | Q11: 0 | R11: 0 | S11: 0 | T11: 0
A12: =SUM(C12:T12) -> 100 | B12: Combat Essence | C12: 100 | D12: 0 | E12: 0 | F12: 0 | G12: 0 | H12: 0 | I12: 0 | J12: 0 | K12: 0 | L12: 0 | M12: 0 | N12: 0 | O12: 0 | P12: 0 | Q12: 0 | R12: 0 | S12: 0 | T12: 0
A13: =SUM(C13:T13) -> 120 | B13: Devilish Soul | C13: 120 | D13: 0 | E13: 0 | F13: 0 | G13: 0 | H13: 0 | I13: 0 | J13: 0 | K13: 0 | L13: 0 | M13: 0 | N13: 0 | O13: 0 | P13: 0 | Q13: 0 | R13: 0 | S13: 0 | T13: 0
A14: =SUM(C14:T14) -> 0 | B14: Divine Soul | C14: 0 | D14: 0 | E14: 0 | F14: 0 | G14: 0 | H14: 0 | I14: 0 | J14: 0 | K14: 0 | L14: 0 | M14: 0 | N14: 0 | O14: 0 | P14: 0 | Q14: 0 | R14: 0 | S14: 0 | T14: 0
A15: =SUM(C15:T15) -> 5000 | B15: Devilish Hide | C15: 5000 | D15: 0 | E15: 0 | F15: 0 | G15: 0 | H15: 0 | I15: 0 | J15: 0 | K15: 0 | L15: 0 | M15: 0 | N15: 0 | O15: 0 | P15: 0 | Q15: 0 | R15: 0 | S15: 0 | T15: 0
A16: =SUM(C16:T16) -> 0 | B16: Divine Hide | C16: 0 | D16: 0 | E16: 0 | F16: 0 | G16: 0 | H16: 0 | I16: 0 | J16: 0 | K16: 0 | L16: 0 | M16: 0 | N16: 0 | O16: 0 | P16: 0 | Q16: 0 | R16: 0 | S16: 0 | T16: 0
A17: =SUM(C17:T17) -> 200 | B17: Excellent Soul | C17: 200 | D17: 0 | E17: 0 | F17: 0 | G17: 0 | H17: 0 | I17: 0 | J17: 0 | K17: 0 | L17: 0 | M17: 0 | N17: 0 | O17: 0 | P17: 0 | Q17: 0 | R17: 0 | S17: 0 | T17: 0
A18: =SUM(C18:T18) -> 500 | B18: Unreal Essence | C18: 500 | D18: 0 | E18: 0 | F18: 0 | G18: 0 | H18: 0 | I18: 0 | J18: 0 | K18: 0 | L18: 0 | M18: 0 | N18: 0 | O18: 0 | P18: 0 | Q18: 0 | R18: 0 | S18: 0 | T18: 0
A19: =SUM(C19:T19) -> 5000 | B19: Black Pearl | C19: 5000 | D19: 0 | E19: 0 | F19: 0 | G19: 0 | H19: 0 | I19: 0 | J19: 0 | K19: 0 | L19: 0 | M19: 0 | N19: 0 | O19: 0 | P19: 0 | Q19: 0 | R19: 0 | S19: 0 | T19: 0
A20: =SUM(C20:T20) -> 10 | B20: Devilish Essence | C20: 10 | D20: 0 | E20: 0 | F20: 0 | G20: 0 | H20: 0 | I20: 0 | J20: 0 | K20: 0 | L20: 0 | M20: 0 | N20: 0 | O20: 0 | P20: 0 | Q20: 0 | R20: 0 | S20: 0 | T20: 0
... A23: =SUM(C23:T23) -> 0 | B23: Celestial Energy | C23: 0 | D23: 0 | E23: 0 | F23: 0 | G23: 0 | H23: 0 | I23: 0 | J23: 0 | K23: 0 | L23: 0 | M23: 0 | N23: 0 | O23: 0 | P23: 0 | Q23: 0 | R23: 0 | S23: 0 | T23: 0
C24: 0 | D24: 0 | E24: 0 | F24: 0 | G24: 0 | H24: 0 | I24: 0 | J24: 0 | K24: 0 | L24: 0 | M24: 0 | N24: 0 | O24: 0 | P24: 0 | Q24: 0 | R24: 0 | S24: 0 | T24: 0
A25: =SUM(C25:T25) -> 0 | B25: Chaos Warchief Soul | C25: 0 | D25: 0 | E25: 0 | F25: 0 | G25: 0 | H25: 0 | I25: 0 | J25: 0 | K25: 0 | L25: 0 | M25: 0 | N25: 0 | O25: 0 | P25: 0 | Q25: 0 | R25: 0 | S25: 0 | T25: 0
A26: =SUM(C26:T26) -> 0 | B26: Order Warchief Soul | C26: 0 | D26: 0 | E26: 0 | F26: 0 | G26: 0 | H26: 0 | I26: 0 | J26: 0 | K26: 0 | L26: 0 | M26: 0 | N26: 0 | O26: 0 | P26: 0 | Q26: 0 | R26: 0 | S26: 0 | T26: 0
A27: =SUM(C27:T27) -> 0 | B27: Bionic Essence | C27: 0 | D27: 0 | E27: 0 | F27: 0 | G27: 0 | H27: 0 | I27: 0 | J27: 0 | K27: 0 | L27: 0 | M27: 0 | N27: 0 | O27: 0 | P27: 0 | Q27: 0 | R27: 0 | S27: 0 | T27: 0
A28: =SUM(C28:T28) -> 0 | B28: Bionic Soul | C28: 0 | D28: 0 | E28: 0 | F28: 0 | G28: 0 | H28: 0 | I28: 0 | J28: 0 | K28: 0 | L28: 0 | M28: 0 | N28: 0 | O28: 0 | P28: 0 | Q28: 0 | R28: 0 | S28: 0 | T28: 0
A29: =SUM(C29:T29) -> 0 | B29: Descended Ingot | C29: 0 | D29: 0 | E29: 0 | F29: 0 | G29: 0 | H29: 0 | I29: 0 | J29: 0 | K29: 0 | L29: 0 | M29: 0 | N29: 0 | O29: 0 | P29: 0 | Q29: 0 | R29: 0 | S29: 0 | T29: 0
C30: 0 | D30: 0 | E30: 0 | F30: 0 | G30: 0 | H30: 0 | I30: 0 | J30: 0 | K30: 0 | L30: 0 | M30: 0 | N30: 0 | O30: 0 | P30: 0 | Q30: 0 | R30: 0 | S30: 0 | T30: 0
A31: =SUM(C31:T31) -> 0 | B31: Ascended Warden Essence | C31: 0 | D31: 0 | E31: 0 | F31: 0 | G31: 0 | H31: 0 | I31: 0 | J31: 0 | K31: 0 | L31: 0 | M31: 0 | N31: 0 | O31: 0 | P31: 0 | Q31: 0 | R31: 0 | S31: 0 | T31: 0
A32: =SUM(C32:T32) -> 0 | B32: Descended Warden essence | C32: 0 | D32: 0 | E32: 0 | F32: 0 | G32: 0 | H32: 0 | I32: 0 | J32: 0 | K32: 0 | L32: 0 | M32: 0 | N32: 0 | O32: 0 | P32: 0 | Q32: 0 | R32: 0 | S32: 0 | T32: 0
A33: =SUM(C33:T33) -> 0 | B33: Luminous Essence | C33: 0 | D33: 0 | E33: 0 | F33: 0 | G33: 0 | H33: 0 | I33: 0 | J33: 0 | K33: 0 | L33: 0 | M33: 0 | N33: 0 | O33: 0 | P33: 0 | Q33: 0 | R33: 0 | S33: 0 | T33: 0
A34: =SUM(C34:T34) -> 0 | B34: Ancient Essence (Os) | C34: 0 | D34: 0 | E34: 0 | F34: 0 | G34: 0 | H34: 0 | I34: 0 | J34: 0 | K34: 0 | L34: 0 | M34: 0 | N34: 0 | O34: 0 | P34: 0 | Q34: 0 | R34: 0 | S34: 0 | T34: 0
C35: 0 | D35: 0 | E35: 0 | F35: 0 | G35: 0 | H35: 0 | I35: 0 | J35: 0 | K35: 0 | L35: 0 | M35: 0 | N35: 0 | O35: 0 | P35: 0 | Q35: 0 | R35: 0 | S35: 0 | T35: 0
A36: =SUM(C36:T36) -> 0 | B36: Bionic Gigant Essence | C36: 0 | D36: 0 | E36: 0 | F36: 0 | G36: 0 | H36: 0 | I36: 0 | J36: 0 | K36: 0 | L36: 0 | M36: 0 | N36: 0 | O36: 0 | P36: 0 | Q36: 0 | R36: 0 | S36: 0 | T36: 0
A37: =SUM(C37:T37) -> 0 | B37: Descended Essence | C37: 0 | D37: 0 | E37: 0 | F37: 0 | G37: 0 | H37: 0 | I37: 0 | J37: 0 | K37: 0 | L37: 0 | M37: 0 | N37: 0 | O37: 0 | P37: 0 | Q37: 0 | R37: 0 | S37: 0 | T37: 0
A38: =SUM(C38:T38) -> 0 | B38: Excellent Essence | C38: 0 | D38: 0 | E38: 0 | F38: 0 | G38: 0 | H38: 0 | I38: 0 | J38: 0 | K38: 0 | L38: 0 | M38: 0 | N38: 0 | O38: 0 | P38: 0 | Q38: 0 | R38: 0 | S38: 0 | T38: 0
A39: =SUM(C39:T39) -> 0 | B39: Warden Rex Trophy | C39: 0 | D39: 0 | E39: 0 | F39: 0 | G39: 0 | H39: 0 | I39: 0 | J39: 0 | K39: 0 | L39: 0 | M39: 0 | N39: 0 | O39: 0 | P39: 0 | Q39: 0 | R39: 0 | S39: 0 | T39: 0
A40: =SUM(C40:T40) -> 0 | B40: Warden Spino Trophy | C40: 0 | D40: 0 | E40: 0 | F40: 0 | G40: 0 | H40: 0 | I40: 0 | J40: 0 | K40: 0 | L40: 0 | M40: 0 | N40: 0 | O40: 0 | P40: 0 | Q40: 0 | R40: 0 | S40: 0 | T40: 0
A41: =SUM(C41:T41) -> 0 | B41: Warden Theri Trophy | C41: 0 | D41: 0 | E41: 0 | F41: 0 | G41: 0 | H41: 0 | I41: 0 | J41: 0 | K41: 0 | L41: 0 | M41: 0 | N41: 0 | O41: 0 | P41: 0 | Q41: 0 | R41: 0 | S41: 0 | T41: 0
A42: =SUM(C42:T42) -> 0 | B42: Warden Lizard Trophy | C42: 0 | D42: 0 | E42: 0 | F42: 0 | G42: 0 | H42: 0 | I42: 0 | J42: 0 | K42: 0 | L42: 0 | M42: 0 | N42: 0 | O42: 0 | P42: 0 | Q42: 0 | R42: 0 | S42: 0 | T42: 0
A43: =SUM(C43:T43) -> 0 | B43: Supreme Warden Giga Trophy | C43: 0 | D43: 0 | E43: 0 | F43: 0 | G43: 0 | H43: 0 | I43: 0 | J43: 0 | K43: 0 | L43: 0 | M43: 0 | N43: 0 | O43: 0 | P43: 0 | Q43: 0 | R43: 0 | S43: 0 | T43: 0
A44: =SUM(C44:T44) -> 0 | B44: Supreme Warden Reaper Trophy | C44: 0 | D44: 0 | E44: 0 | F44: 0 | G44: 0 | H44: 0 | I44: 0 | J44: 0 | K44: 0 | L44: 0 | M44: 0 | N44: 0 | O44: 0 | P44: 0 | Q44: 0 | R44: 0 | S44: 0 | T44: 0
C45: 0 | D45: 0 | E45: 0 | F45: 0 | G45: 0 | H45: 0 | I45: 0 | J45: 0 | K45: 0 | L45: 0 | M45: 0 | N45: 0 | O45: 0 | P45: 0 | Q45: 0 | R45: 0 | S45: 0 | T45: 0
A46: =SUM(C46:T46) -> 0 | B46: Soul of Ascension God | C46: 0 | D46: 0 | E46: 0 | F46: 0 | G46: 0 | H46: 0 | I46: 0 | J46: 0 | K46: 0 | L46: 0 | M46: 0 | N46: 0 | O46: 0 | P46: 0 | Q46: 0 | R46: 0 | S46: 0 | T46: 0
A47: =SUM(C47:T47) -> 0 | B47: Soul of Descension God | C47: 0 | D47: 0 | E47: 0 | F47: 0 | G47: 0 | H47: 0 | I47: 0 | J47: 0 | K47: 0 | L47: 0 | M47: 0 | N47: 0 | O47: 0 | P47: 0 | Q47: 0 | R47: 0 | S47: 0 | T47: 0
...

Sheet Key Calculator v1
C2: CRAFT NORMAL | E2: CRAFT GOD KEY
A3: TOTAL | B3: Compos | C3: Abyssal Warfare Key | D3: Celestial Warfare key | E3: Abyssal (6) + Celestial (6)
A4: =SUM(C4:E4) -> 0 | B4: Abyssal Carcha Trophy | C4: {=Feuille1!C55:C94*$H$6} -> 0 | D4: {=Feuille1!D55:D94*$H$8} -> 0 | E4: {=Feuille1!E55:E94*$H$11} -> 0 | G4: Combien de Clef veux tu ? (Normal craft)
A5: =SUM(C5:E5) -> 0 | B5: Abyssal Dodoreaper Trophy | C5: 0 | D5: 0 | E5: 0 | G5: Abyssal Warfare Key | J5: Equivaut à :
A6: =SUM(C6:E6) -> 0 | B6: Abyssal Dodorexy Trophy | C6: 0 | D6: 0 | E6: 0 | G6: Nombre : | H6: 0 | J6: =SUM(H6/6) -> 0 | K6: God Key
A7: =SUM(C7:E7) -> 0 | B7: Abyssal Drake Trophy | C7: 0 | D7: 0 | E7: 0 | G7: Celestial Warfare key
A8: =SUM(C8:E8) -> 0 | B8: Abyssal Indominus Rex Trophy | C8: 0 | D8: 0 | E8: 0 | G8: Nombre : | H8: 0 | J8: =SUM(H8/6) -> 0 | K8: God Key
A9: =SUM(C9:E9) -> 0 | B9: Abyssal Manticore Trophy | C9: 0 | D9: 0 | E9: 0
A10: =SUM(C10:E10) -> 0 | B10: Abyssal Spider Trophy | C10: 0 | D10: 0 | E10: 0 | G10: God Key
A11: =SUM(C11:E11) -> 0 | B11: Abyssal Element | C11: 0 | D11: 0 | E11: 0 | G11: Nombre :
A12: =SUM(C12:E12) -> 0 | B12: Abyssal Energy | C12: 0 | D12: 0 | E12: 0
C13: 0 | D13: 0 | E13: 0
A14: =SUM(C14:E14) -> 0 | B14: Celestial Gigant Trophy | C14: 0 | D14: 0 | E14: 0
A15: =SUM(C15:E15) -> 0 | B15: Celestial Gorilla Trophy | C15: 0 | D15: 0 | E15: 0
A16: =SUM(C16:E16) -> 0 | B16: Celestial Rhynio Trophy | C16: 0 | D16: 0 | E16: 0
A17: =SUM(C17:E17) -> 0 | B17: Celestial Rock Golem trophy | C17: 0 | D17: 0 | E17: 0
A18: =SUM(C18:E18) -> 0 | B18: Celestial Rock Drake Trophy | C18: 0 | D18: 0 | E18: 0
A19: =SUM(C19:E19) -> 0 | B19: Celestial Titano Trophy | C19: 0 | D19: 0 | E19: 0
A20: =SUM(C20:E20) -> 0 | B20: Celestial Wyvern Trophy | C20: 0 | D20: 0 | E20: 0
A21: =SUM(C21:E21) -> 0 | B21: Celestial Element | C21: 0 | D21: 0 | E21: 0
A22: =SUM(C22:E22) -> 0 | B22: Celestial Energy | C22: 0 | D22: 0 | E22: 0
C23: 0 | D23: 0 | E23: 0
A24: =SUM(C24:E24) -> 0 | B24: Ancient Token Cluster | C24: 0 | D24: 0 | E24: 0
A25: =SUM(C25:E25) -> 0 | B25: Element | C25: 0 | D25: 0 | E25: 0
A26: =SUM(C26:E26) -> 0 | B26: Black Pearl | C26: 0 | D26: 0 | E26: 0
A27: =SUM(C27:E27) -> 0 | B27: Unreal Essence | C27: 0 | D27: 0 | E27: 0
A28: =SUM(C28:E28) -> 0 | B28: Oracle Essence | C28: 0 | D28: 0 | E28: 0
C29: 0 | D29: 0 | E29: 0
A30: =SUM(C30:E30) -> 0 | B30: Abyssal Carcha Soul | C30: 0 | D30: 0 | E30: 0
A31: =SUM(C31:E31) -> 0 | B31: Abyssal Dodoreaper Soul | C31: 0 | D31: 0 | E31: 0
A32: =SUM(C32:E32) -> 0 | B32: Abyssal Dodorexy Soul | C32: 0 | D32: 0 | E32: 0
A33: =SUM(C33:E33) -> 0 | B33: Abyssal Drake Soul | C33: 0 | D33: 0 | E33: 0
A34: =SUM(C34:E34) -> 0 | B34: Abyssal Indominus Rex Soul | C34: 0 | D34: 0 | E34: 0
A35: =SUM(C35:E35) -> 0 | B35: Abyssal Manticore Soul | C35: 0 | D35: 0 | E35: 0
A36: =SUM(C36:E36) -> 0 | B36: Abyssal Spider Soul | C36: 0 | D36: 0 | E36: 0
A37: =SUM(C37:E37) -> 0 | B37: Celestial Gigant Soul | C37: 0 | D37: 0 | E37: 0
A38: =SUM(C38:E38) -> 0 | B38: Celestial Gorilla Soul | C38: 0 | D38: 0 | E38: 0
A39: =SUM(C39:E39) -> 0 | B39: Celestial Rhynio Soul | C39: 0 | D39: 0 | E39: 0
A40: =SUM(C40:E40) -> 0 | B40: Celestial Rock Golem Soul | C40: 0 | D40: 0 | E40: 0
A41: =SUM(C41:E41) -> 0 | B41: Celestial Rock Drake Soul | C41: 0 | D41: 0 | E41: 0
...

Sheet Ancient Token Calculator v1
C3: Ancient Token Cluster | E3: Combien veux tu d'Ancient Token Cluster ? | I3: Tu changes ici
B4: Compos | C4: Ancient Token Cluster
B5: Raptor Token | C5: {=Feuille1!C98:C106*$G$3} -> 0 | E5: Nombre de chaque mob à faire = (En moyenne) | G5: =SUM(C5/20) -> 0
B6: Carno Token | C6: 0
B7: Bronto Token | C7: 0
B8: Giga Token | C8: 0
B9: Rex Token | C9: 0
B10: Trice Token | C10: 0
B11: Stego Token | C11: 0
B12: Quetz Token | C12: 0
B13: Wyvern Token | C13: 0
C15: Ancient Dino
A16: TOTAL | B16: compos | C16: Token
A17: =SUM(C17) -> 0 | B17: Black Pearl | C17: {=Feuille1!F98:F103*$C$23} -> 0
A18: =SUM(C18) -> 0 | B18: Excellent Essence | C18: 0
A19: =SUM(C19) -> 0 | B19: Unreal Essence | C19: 0
A20: =SUM(C20) -> 0 | B20: Excellent Soul | C20: 0
A21: =SUM(C21) -> 0 | B21: Descended Essence | C21: 0
A22: =SUM(C22) -> 0 | B22: Artifact | C22: 0
B23: Nombre : | C23: 0

Sheet Feuille1
C5: T4 | E5: T5 | H5: T6 | J5: T7 | N5: T8 | P5: T9
B7: Compos | C7: Abyssal | D7: Celestial | E7: Nidhogg | F7: Chaos (rouge) | G7: Order (blue) | H7: Normal | I7: Giga | J7: Dodo Bleu | K7: Dodo Rouge | L7: W. Reaper | M7: W. Giga | N7: Ascension | O7: Descension | P7: 1 Seal | Q7: 2 Seal | R7: 3 Seal | S7: 4 Seal | T7: Cube
B8: Artefact | C8: 2 | D8: 2 | E8: 4 | F8: 3 | G8: 3 | H8: 3 | I8: 3 | J8: 3 | K8: 3 | L8: 3 | M8: 3 | N8: 5 | O8: 5 | P8: 3 | Q8: 5 | R8: 5 | S8: 5 | T8: 3
B9: Abyssal Warfare Key | E9: 1 | F9: 1 | G9: 1 | N9: 1 | O9: 1 | P9: 1 | Q9: 1 | R9: 1 | S9: 1 | T9: 1
B10: Celestial Warfare key | E10: 1 | F10: 1 | G10: 1 | N10: 1 | O10: 1 | P10: 1 | Q10: 1 | R10: 1 | S10: 1 | T10: 1
B11: Ancient token Cluster | C11: 1 | D11: 1 | E11: 3 | F11: 1 | G11: 1 | H11: 2 | I11: 3 | J11: 2 | K11: 2 | L11: 2 | M11: 2 | N11: 3 | O11: 3 | P11: 5 | Q11: 6 | R11: 6 | S11: 6 | T11: 3
B12: Combat Essence | C12: 10 | D12: 10 | E12: 10 | F12: 10 | G12: 10 | L12: 10 | M12: 10
B13: Devilish Soul | C13: 12 | E13: 24 | F13: 10 | G13: 10 | H13: 10 | I13: 15 | J13: 10 | K13: 10 | L13: 15 | M13: 15 | N13: 40 | O13: 40 | P13: 35 | Q13: 40 | R13: 40 | S13: 60 | T13: 40
B14: Divine Soul | D14: 12 | E14: 24 | F14: 10 | G14: 10 | H14: 10 | I14: 15 | J14: 10 | K14: 10 | L14: 15 | M14: 15 | N14: 40 | O14: 40 | P14: 35 | Q14: 40 | R14: 40 | S14: 60 | T14: 40
B15: Devilish Hide | C15: 500 | E15: 3000 | F15: 1000 | G15: 1000 | H15: 1000 | I15: 2000 | J15: 1000 | K15: 1000 | L15: 1000 | M15: 1000 | T15: 5000
B16: Divine Hide | D16: 500 | E16: 3000 | F16: 1000 | G16: 1000 | H16: 1000 | I16: 2000 | J16: 1000 | K16: 1000 | L16: 1000 | M16: 1000 | T16: 5000
B17: Excellent Soul | C17: 20 | D17: 20 | E17: 30 | F17: 25 | G17: 25 | H17: 25 | I17: 30 | J17: 20 | K17: 20 | L17: 30 | M17: 30 | N17: 60 | O17: 60 | T17: 60
B18: Unreal Essence | C18: 50 | D18: 50 | E18: 1000 | F18: 100 | G18: 100
B19: Black Pearl | C19: 500 | D19: 500 | E19: 1500 | F19: 1000 | G19: 1000 | H19: 1000 | I19: 1500 | J19: 800 | K19: 800 | L19: 1000 | M19: 1000 | N19: 2000 | O19: 2000 | P19: 1000 | Q19: 1500 | R19: 1500 | S19: 1500 | T19: 2000
B20: Devilish Essence | C20: 1
B21: Divin Essence | D21: 1
B22: Abyssal Energy | C22: 10
B23: Celestial Energy | D23: 10
B25: Chaos Warchief Soul | H25: 2 | I25: 2
B26: Order Warchief Soul | H26: 2 | I26: 2
B27: Bionic Essence | I27: 500
B28: Bionic Soul | J28: 5 | K28: 5 | L28: 6 | M28: 6
B29: Descended Ingot | J29: 400 | K29: 400 | L29: 800 | M29: 800 | P29: 500 | Q29: 450 | R29: 450 | S29: 600
B31: Ascended Warden Essence | M31: 5 | N31: 10 | T31: 8
B32: Descended Warden essence | L32: 5 | O32: 10 | T32: 8
B33: Luminous Essence | L33: 200
B34: Ancient Essence (Os) | M34: 1000
B36: Bionic Gigant Essence | N36: 1 | O36: 1
B37: Descended Essence | L37: 1000 | M37: 1000 | N37: 2500 | O37: 2500 | P37: 2000 | Q37: 3000 | R37: 3000 | S37: 3000
B38: Excellent Essence | N38: 2000 | O38: 2000
B39: Warden Rex Trophy | N39: 5 | O39: 5
B40: Warden Spino Trophy | N40: 5 | O40: 5
B41: Warden Theri Trophy | N41: 5 | O41: 5
B42: Warden Lizard Trophy | N42: 5 | O42: 5
B43: Supreme Warden Giga Trophy | N43: 1 | O43: 1 | T43: 1
B44: Supreme Warden Reaper Trophy | N44: 1 | O44: 1 | T44: 1
B46: Soul of Ascension God | P46: 1 | Q46: 1 | R46: 1 | S46: 1 | T46: 1
B47: Soul of Descension God | P47: 1 | Q47: 1 | R47: 1 | S47: 1 | T47: 1
B48: Seal Fragments | T48: 2
B50: Nombre : | C50: 0 | D50: 0 | E50: 0 | F50: 0 | G50: 0 | H50: 0 | I50: 0 | J50: 0 | K50: 0 | L50: 0 | M50: 0 | N50: 0 | O50: 0 | P50: 0 | Q50: 0 | R50: 0 | S50: 0 | T50: 0
...
